Workbook

Sheet Config
A1: Ultimo Aggiornamento | B1: 46172.128
A3: La colonna F è importante e colorata di azzurro perchè ha le formule per andare a prendere i risultati dalle annate precedenti, dopo averli calcolati è stato fatto copia e incolla valori, per non avere forumule inutili

Sheet Gestionale_
A1: Colonna 1 | B1: Giocatore | C1: Squadra Fantacalcio | D1: Squadra Serie A | E1: Ruolo | F1: Tipo contratto | G1: Data acquisto | H1: Scadenza ipotizzata | I1: Tipo Acquisto | J1: (*) Val Asteriscato | K1: SCAMBIO % ingaggio pagato | L1: Valore Acquisto (da leghe) | M1: FVM 25/26 o precedenti | N1: Ultimo FVM | O1: Valore 1 luglio | P1: Valore x Mercato 25/26 | Q1: Ingaggio 36 giornate | R1: Ingaggio reale | S1: Crediti ricevuti da acquisto/scambio | T1: Squadra Proprietaria Originale | U1: NOTE | V1: Colonna 22 | W1: Colonna 23 | X1: Colonna 24 | Y1: Colonna 25 | Z1: Colonna 26 | AA1: Colonna 27 | AB1: Colonna 28 | AC1: Colonna 29 | AD1: Colonna 30 | AE1: Colonna 31 | AF1: Colonna 32 | AG1: Colonna 33 | AH1: Colonna 34 | AI1: Colonna 35 | AJ1: Colonna 36 | AK1: Colonna 37 | AL1: Colonna 38 | AM1: Colonna 39
A2: =VLOOKUP(B2,FVM_update!A:B,2,0) -> 6593 | B2: Akinsanmiro | C2: AS Intomatici | D2: =VLOOKUP(B2,FVM_update!A:F,6,0) -> Pisa | E2: =VLOOKUP(B2,FVM_update!A:E,4,0) -> C;T | F2: Vivaio | G2: 45839 | H2: =IF(F2="Vivaio", DATE(2999, 12, 31), IF(F2="Standard", DATE(YEAR(G2)+1, MONTH(G2), DAY(G2)), IF(F2="Standard Inverno", DATE(2026, 7, 1), IF(OR(F2="Diritto 1+1", F2="Obbligo 1+1"), DATE(YEAR(G2)+2, MONTH(G2), DAY(G2)), IF(F2="Obbligo 1+2", DATE(YEAR(G2)+3, MONTH(G2), DAY(G2)), IF(OR(F2="Inverno Obbligo 1,5", F2="Inverno Diritto 0,5 + 1"), DATE(YEAR(G2)+1, MONTH(G2)+6, DAY(G2)), IF(F2="Inverno Obbligo 2,5", DATE(YEAR(G2)+2, MONTH(G2)+6, DAY(G2)), G2) ) ) ) ) ) ) -> 401768 | I2: Vivaio | J2: =VLOOKUP(A2,Asteriscati25!B:N,13,0) -> #N/A | L2: =VLOOKUP(B2,Rose!B:D,3,0) -> #REF! | M2: =VLOOKUP(B2,FVM_Asta2526!A:N,14,0) -> 13 | N2: =VLOOKUP(A2,FVM_update!B:N,13,0) -> 12 | O2: =VLOOKUP(B2,'FVM_1luglio-31luglio25'!D:Q,14,0) -> #N/A | P2: =IFERROR(N2,O2) -> 12 | Q2: =IF(OR(F2="Standard",F2="Standard Inverno"),CEILING((M2/10),0.5), IF(OR(F2="Diritto 1+1",M2="Inverno Diritto 0,5 + 1"),CEILING((M2/10)*1.3,0.5), CEILING((M2/10)*1.15,0.5))) -> 1.5 | R2: =IF(I2="vivaio", 0.5, IF(OR(I2="asta", I2="Svincolato riconferma anno corrente", I2="vivaio", I2="promosso da vivaio"), Q2, IF(OR(I2="asta riparazione", I2="Svincolato obbligo anno precedente", I2="Svincolo pausa invernale"), MAX(0.5, CEILING(Q2 / 2, 0.5)), IF(OR(I2="ceduto in prestito", I2="acquisito in prestito", I2="acquistato tit definitivo", I2="Ceduto tit definitivo"),CEILING(Q2 * K2, 0.5), IF(I2="asteriscato", "inserire a mano", "")))) ) -> 0.5
A3: =VLOOKUP(B3,FVM_update!A:B,2,0) -> 4772 | B3: ANGELINO | C3: AS Intomatici | D3: =VLOOKUP(B3,FVM_update!A:F,6,0) -> Roma | E3: =VLOOKUP(B3,FVM_update!A:E,4,0) -> E | F3: Standard | G3: 45839 | H3: =IF(F3="Vivaio", DATE(2999, 12, 31), IF(F3="Standard", DATE(YEAR(G3)+1, MONTH(G3), DAY(G3)), IF(F3="Standard Inverno", DATE(2026, 7, 1), IF(OR(F3="Diritto 1+1", F3="Obbligo 1+1"), DATE(YEAR(G3)+2, MONTH(G3), DAY(G3)), IF(F3="Obbligo 1+2", DATE(YEAR(G3)+3, MONTH(G3), DAY(G3)), IF(OR(F3="Inverno Obbligo 1,5", F3="Inverno Diritto 0,5 + 1"), DATE(YEAR(G3)+1, MONTH(G3)+6, DAY(G3)), IF(F3="Inverno Obbligo 2,5", DATE(YEAR(G3)+2, MONTH(G3)+6, DAY(G3)), G3) ) ) ) ) ) ) -> 46204 | I3: Svincolo pausa invernale | J3: =VLOOKUP(A3,Asteriscati25!B:N,13,0) -> #N/A | L3: =VLOOKUP(B3,Rose!B:D,3,0) -> #REF! | M3: =VLOOKUP(B3,FVM_Asta2526!A:N,14,0) -> 52 | N3: =VLOOKUP(A3,FVM_update!B:N,13,0) -> 10 | O3: =VLOOKUP(B3,'FVM_1luglio-31luglio25'!D:Q,14,0) -> 35 | P3: =IFERROR(N3,O3) -> 10 | Q3: =IF(OR(F3="Standard",F3="Standard Inverno"),CEILING((M3/10),0.5), IF(OR(F3="Diritto 1+1",M3="Inverno Diritto 0,5 + 1"),CEILING((M3/10)*1.3,0.5), CEILING((M3/10)*1.15,0.5))) -> 5.5 | R3: =IF(I3="vivaio", 0.5, IF(OR(I3="asta", I3="Svincolato riconferma anno corrente", I3="vivaio", I3="promosso da vivaio"), Q3, IF(OR(I3="asta riparazione", I3="Svincolato obbligo anno precedente", I3="Svincolo pausa invernale"), MAX(0.5, CEILING(Q3 / 2, 0.5)), IF(OR(I3="ceduto in prestito", I3="acquisito in prestito", I3="acquistato tit definitivo", I3="Ceduto tit definitivo"),CEILING(Q3 * K3, 0.5), IF(I3="asteriscato", "inserire a mano", "")))) ) -> 3
A4: =VLOOKUP(B4,FVM_update!A:B,2,0) -> 761 | B4: AUDERO | C4: AS Intomatici | D4: =VLOOKUP(B4,FVM_update!A:F,6,0) -> Cremonese | E4: =VLOOKUP(B4,FVM_update!A:E,4,0) -> Por | F4: Standard | G4: 45839 | H4: =IF(F4="Vivaio", DATE(2999, 12, 31), IF(F4="Standard", DATE(YEAR(G4)+1, MONTH(G4), DAY(G4)), IF(F4="Standard Inverno", DATE(2026, 7, 1), IF(OR(F4="Diritto 1+1", F4="Obbligo 1+1"), DATE(YEAR(G4)+2, MONTH(G4), DAY(G4)), IF(F4="Obbligo 1+2", DATE(YEAR(G4)+3, MONTH(G4), DAY(G4)), IF(OR(F4="Inverno Obbligo 1,5", F4="Inverno Diritto 0,5 + 1"), DATE(YEAR(G4)+1, MONTH(G4)+6, DAY(G4)), IF(F4="Inverno Obbligo 2,5", DATE(YEAR(G4)+2, MONTH(G4)+6, DAY(G4)), G4) ) ) ) ) ) ) -> 46204 | I4: Asta | J4: =VLOOKUP(A4,Asteriscati25!B:N,13,0) -> #N/A | L4: =VLOOKUP(B4,Rose!B:D,3,0) -> #REF! | M4: =VLOOKUP(B4,FVM_Asta2526!A:N,14,0) -> 13 | N4: =VLOOKUP(A4,FVM_update!B:N,13,0) -> 11 | O4: =VLOOKUP(B4,'FVM_1luglio-31luglio25'!D:Q,14,0) -> #N/A | P4: =IFERROR(N4,O4) -> 11 | Q4: =IF(OR(F4="Standard",F4="Standard Inverno"),CEILING((M4/10),0.5), IF(OR(F4="Diritto 1+1",M4="Inverno Diritto 0,5 + 1"),CEILING((M4/10)*1.3,0.5), CEILING((M4/10)*1.15,0.5))) -> 1.5 | R4: =IF(I4="vivaio", 0.5, IF(OR(I4="asta", I4="Svincolato riconferma anno corrente", I4="vivaio", I4="promosso da vivaio"), Q4, IF(OR(I4="asta riparazione", I4="Svincolato obbligo anno precedente", I4="Svincolo pausa invernale"), MAX(0.5, CEILING(Q4 / 2, 0.5)), IF(OR(I4="ceduto in prestito", I4="acquisito in prestito", I4="acquistato tit definitivo", I4="Ceduto tit definitivo"),CEILING(Q4 * K4, 0.5), IF(I4="asteriscato", "inserire a mano", "")))) ) -> 1.5
A5: =VLOOKUP(B5,FVM_update!A:B,2,0) -> 184 | B5: BERNARDESCHI | C5: AS Intomatici | D5: =VLOOKUP(B5,FVM_update!A:F,6,0) -> Bologna | E5: =VLOOKUP(B5,FVM_update!A:E,4,0) -> W;A | F5: Standard | G5: 45839 | H5: =IF(F5="Vivaio", DATE(2999, 12, 31), IF(F5="Standard", DATE(YEAR(G5)+1, MONTH(G5), DAY(G5)), IF(F5="Standard Inverno", DATE(2026, 7, 1), IF(OR(F5="Diritto 1+1", F5="Obbligo 1+1"), DATE(YEAR(G5)+2, MONTH(G5), DAY(G5)), IF(F5="Obbligo 1+2", DATE(YEAR(G5)+3, MONTH(G5), DAY(G5)), IF(OR(F5="Inverno Obbligo 1,5", F5="Inverno Diritto 0,5 + 1"), DATE(YEAR(G5)+1, MONTH(G5)+6, DAY(G5)), IF(F5="Inverno Obbligo 2,5", DATE(YEAR(G5)+2, MONTH(G5)+6, DAY(G5)), G5) ) ) ) ) ) ) -> 46204 | I5: Asta | J5: =VLOOKUP(A5,Asteriscati25!B:N,13,0) -> #N/A | L5: =VLOOKUP(B5,Rose!B:D,3,0) -> #REF! | M5: =VLOOKUP(B5,FVM_Asta2526!A:N,14,0) -> 22 | N5: =VLOOKUP(A5,FVM_update!B:N,13,0) -> 12 | O5: =VLOOKUP(B5,'FVM_1luglio-31luglio25'!D:Q,14,0) -> #N/A | P5: =IFERROR(N5,O5) -> 12 | Q5: =IF(OR(F5="Standard",F5="Standard Inverno"),CEILING((M5/10),0.5), IF(OR(F5="Diritto 1+1",M5="Inverno Diritto 0,5 + 1"),CEILING((M5/10)*1.3,0.5), CEILING((M5/10)*1.15,0.5))) -> 2.5 | R5: =IF(I5="vivaio", 0.5, IF(OR(I5="asta", I5="Svincolato riconferma anno corrente", I5="vivaio", I5="promosso da vivaio"), Q5, IF(OR(I5="asta riparazione", I5="Svincolato obbligo anno precedente", I5="Svincolo pausa invernale"), MAX(0.5, CEILING(Q5 / 2, 0.5)), IF(OR(I5="ceduto in prestito", I5="acquisito in prestito", I5="acquistato tit definitivo", I5="Ceduto tit definitivo"),CEILING(Q5 * K5, 0.5), IF(I5="asteriscato", "inserire a mano", "")))) ) -> 2.5
A6: =VLOOKUP(B6,FVM_update!A:B,2,0) -> 6495 | B6: Comuzzo | C6: AS Intomatici | D6: =VLOOKUP(B6,FVM_update!A:F,6,0) -> Fiorentina | E6: =VLOOKUP(B6,FVM_update!A:E,4,0) -> Dc | F6: Standard | G6: 45839 | H6: =IF(F6="Vivaio", DATE(2999, 12, 31), IF(F6="Standard", DATE(YEAR(G6)+1, MONTH(G6), DAY(G6)), IF(F6="Standard Inverno", DATE(2026, 7, 1), IF(OR(F6="Diritto 1+1", F6="Obbligo 1+1"), DATE(YEAR(G6)+2, MONTH(G6), DAY(G6)), IF(F6="Obbligo 1+2", DATE(YEAR(G6)+3, MONTH(G6), DAY(G6)), IF(OR(F6="Inverno Obbligo 1,5", F6="Inverno Diritto 0,5 + 1"), DATE(YEAR(G6)+1, MONTH(G6)+6, DAY(G6)), IF(F6="Inverno Obbligo 2,5", DATE(YEAR(G6)+2, MONTH(G6)+6, DAY(G6)), G6) ) ) ) ) ) ) -> 46204 | I6: Promosso da vivaio | J6: =VLOOKUP(A6,Asteriscati25!B:N,13,0) -> #N/A | K6: 0 | L6: =VLOOKUP(B6,Rose!B:D,3,0) -> #REF! | M6: =VLOOKUP(B6,FVM_Asta2526!A:N,14,0) -> 17 | N6: =VLOOKUP(A6,FVM_update!B:N,13,0) -> 16 | O6: =VLOOKUP(B6,'FVM_1luglio-31luglio25'!D:Q,14,0) -> 11 | P6: =IFERROR(N6,O6) -> 16 | Q6: =IF(OR(F6="Standard",F6="Standard Inverno"),CEILING((M6/10),0.5), IF(OR(F6="Diritto 1+1",M6="Inverno Diritto 0,5 + 1"),CEILING((M6/10)*1.3,0.5), CEILING((M6/10)*1.15,0.5))) -> 2 | R6: =IF(I6="vivaio", 0.5, IF(OR(I6="asta", I6="Svincolato riconferma anno corrente", I6="vivaio", I6="promosso da vivaio"), Q6, IF(OR(I6="asta riparazione", I6="Svincolato obbligo anno precedente", I6="Svincolo pausa invernale"), MAX(0.5, CEILING(Q6 / 2, 0.5)), IF(OR(I6="ceduto in prestito", I6="acquisito in prestito", I6="acquistato tit definitivo", I6="Ceduto tit definitivo"),CEILING(Q6 * K6, 0.5), IF(I6="asteriscato", "inserire a mano", "")))) ) -> 2
A7: =VLOOKUP(B7,FVM_update!A:B,2,0) -> #N/A | B7: Corazza | C7: AS Intomatici | D7: =VLOOKUP(B7,FVM_update!A:F,6,0) -> #N/A | E7: =VLOOKUP(B7,FVM_update!A:E,4,0) -> #N/A | F7: Vivaio | G7: 45474 | H7: =IF(F7="Vivaio", DATE(2999, 12, 31), IF(F7="Standard", DATE(YEAR(G7)+1, MONTH(G7), DAY(G7)), IF(F7="Standard Inverno", DATE(2026, 7, 1), IF(OR(F7="Diritto 1+1", F7="Obbligo 1+1"), DATE(YEAR(G7)+2, MONTH(G7), DAY(G7)), IF(F7="Obbligo 1+2", DATE(YEAR(G7)+3, MONTH(G7), DAY(G7)), IF(OR(F7="Inverno Obbligo 1,5", F7="Inverno Diritto 0,5 + 1"), DATE(YEAR(G7)+1, MONTH(G7)+6, DAY(G7)), IF(F7="Inverno Obbligo 2,5", DATE(YEAR(G7)+2, MONTH(G7)+6, DAY(G7)), G7) ) ) ) ) ) ) -> 401768 | I7: Vivaio | J7: =VLOOKUP(A7,Asteriscati25!B:N,13,0) -> #N/A | K7: 0 | L7: =VLOOKUP(B7,Rose!B:D,3,0) -> #REF! | M7: =VLOOKUP(B7,FVM_Asta2425!A:M,13,0) -> 1 | N7: =VLOOKUP(A7,FVM_update!B:N,13,0) -> #N/A | O7: =VLOOKUP(B7,'FVM_1luglio-31luglio25'!D:Q,14,0) -> #N/A | P7: 0 | Q7: =IF(OR(F7="Standard",F7="Standard Inverno"),CEILING((M7/10),0.5), IF(OR(F7="Diritto 1+1",M7="Inverno Diritto 0,5 + 1"),CEILING((M7/10)*1.3,0.5), CEILING((M7/10)*1.15,0.5))) -> 0.5 | R7: =IF(I7="vivaio", 0.5, IF(OR(I7="asta", I7="Svincolato riconferma anno corrente", I7="vivaio", I7="promosso da vivaio"), Q7, IF(OR(I7="asta riparazione", I7="Svincolato obbligo anno precedente", I7="Svincolo pausa invernale"), MAX(0.5, CEILING(Q7 / 2, 0.5)), IF(OR(I7="ceduto in prestito", I7="acquisito in prestito", I7="acquistato tit definitivo", I7="Ceduto tit definitivo"),CEILING(Q7 * K7, 0.5), IF(I7="asteriscato", "inserire a mano", "")))) ) -> 0.5
A8: =VLOOKUP(B8,FVM_update!A:B,2,0) -> 779 | B8: CRISTANTE | C8: AS Intomatici | D8: =VLOOKUP(B8,FVM_update!A:F,6,0) -> Roma | E8: =VLOOKUP(B8,FVM_update!A:E,4,0) -> M;C | F8: Standard | G8: 45839 | H8: =IF(F8="Vivaio", DATE(2999, 12, 31), IF(F8="Standard", DATE(YEAR(G8)+1, MONTH(G8), DAY(G8)), IF(F8="Standard Inverno", DATE(2026, 7, 1), IF(OR(F8="Diritto 1+1", F8="Obbligo 1+1"), DATE(YEAR(G8)+2, MONTH(G8), DAY(G8)), IF(F8="Obbligo 1+2", DATE(YEAR(G8)+3, MONTH(G8), DAY(G8)), IF(OR(F8="Inverno Obbligo 1,5", F8="Inverno Diritto 0,5 + 1"), DATE(YEAR(G8)+1, MONTH(G8)+6, DAY(G8)), IF(F8="Inverno Obbligo 2,5", DATE(YEAR(G8)+2, MONTH(G8)+6, DAY(G8)), G8) ) ) ) ) ) ) -> 46204 | I8: Asta | J8: =VLOOKUP(A8,Asteriscati25!B:N,13,0) -> #N/A | L8: =VLOOKUP(B8,Rose!B:D,3,0) -> #REF! | M8: =VLOOKUP(B8,FVM_Asta2526!A:N,14,0) -> 25 | N8: =VLOOKUP(A8,FVM_update!B:N,13,0) -> 33 | O8: =VLOOKUP(B8,'FVM_1luglio-31luglio25'!D:Q,14,0) -> 29 | P8: =IFERROR(N8,O8) -> 33 | Q8: =IF(OR(F8="Standard",F8="Standard Inverno"),CEILING((M8/10),0.5), IF(OR(F8="Diritto 1+1",M8="Inverno Diritto 0,5 + 1"),CEILING((M8/10)*1.3,0.5), CEILING((M8/10)*1.15,0.5))) -> 2.5 | R8: =IF(I8="vivaio", 0.5, IF(OR(I8="asta", I8="Svincolato riconferma anno corrente", I8="vivaio", I8="promosso da vivaio"), Q8, IF(OR(I8="asta riparazione", I8="Svincolato obbligo anno precedente", I8="Svincolo pausa invernale"), MAX(0.5, CEILING(Q8 / 2, 0.5)), IF(OR(I8="ceduto in prestito", I8="acquisito in prestito", I8="acquistato tit definitivo", I8="Ceduto tit definitivo"),CEILING(Q8 * K8, 0.5), IF(I8="asteriscato", "inserire a mano", "")))) ) -> 2.5
A9: =VLOOKUP(B9,FVM_update!A:B,2,0) -> 5544 | B9: DAVID | C9: AS Intomatici | D9: =VLOOKUP(B9,FVM_update!A:F,6,0) -> Juventus | E9: =VLOOKUP(B9,FVM_update!A:E,4,0) -> Pc | F9: Diritto 1+1 | G9: 45839 | H9: =IF(F9="Vivaio", DATE(2999, 12, 31), IF(F9="Standard", DATE(YEAR(G9)+1, MONTH(G9), DAY(G9)), IF(F9="Standard Inverno", DATE(2026, 7, 1), IF(OR(F9="Diritto 1+1", F9="Obbligo 1+1"), DATE(YEAR(G9)+2, MONTH(G9), DAY(G9)), IF(F9="Obbligo 1+2", DATE(YEAR(G9)+3, MONTH(G9), DAY(G9)), IF(OR(F9="Inverno Obbligo 1,5", F9="Inverno Diritto 0,5 + 1"), DATE(YEAR(G9)+1, MONTH(G9)+6, DAY(G9)), IF(F9="Inverno Obbligo 2,5", DATE(YEAR(G9)+2, MONTH(G9)+6, DAY(G9)), G9) ) ) ) ) ) ) -> 46569 | I9: Asta | J9: =VLOOKUP(A9,Asteriscati25!B:N,13,0) -> #N/A | L9: =VLOOKUP(B9,Rose!B:D,3,0) -> #REF! | M9: =VLOOKUP(B9,FVM_Asta2526!A:N,14,0) -> 266 | N9: =VLOOKUP(A9,FVM_update!B:N,13,0) -> 58 | O9: =VLOOKUP(B9,'FVM_1luglio-31luglio25'!D:Q,14,0) -> #N/A | P9: =IFERROR(N9,O9) -> 58 | Q9: =IF(OR(F9="Standard",F9="Standard Inverno"),CEILING((M9/10),0.5), IF(OR(F9="Diritto 1+1",M9="Inverno Diritto 0,5 + 1"),CEILING((M9/10)*1.3,0.5), CEILING((M9/10)*1.15,0.5))) -> 35 | R9: =IF(I9="vivaio", 0.5, IF(OR(I9="asta", I9="Svincolato riconferma anno corrente", I9="vivaio", I9="promosso da vivaio"), Q9, IF(OR(I9="asta riparazione", I9="Svincolato obbligo anno precedente", I9="Svincolo pausa invernale"), MAX(0.5, CEILING(Q9 / 2, 0.5)), IF(OR(I9="ceduto in prestito", I9="acquisito in prestito", I9="acquistato tit definitivo", I9="Ceduto tit definitivo"),CEILING(Q9 * K9, 0.5), IF(I9="asteriscato", "inserire a mano", "")))) ) -> 35
A10: =VLOOKUP(B10,FVM_update!A:B,2,0) -> 5995 | B10: DE KETELAERE | C10: AS Intomatici | D10: =VLOOKUP(B10,FVM_update!A:F,6,0) -> Atalanta | E10: =VLOOKUP(B10,FVM_update!A:E,4,0) -> A | F10: Standard | G10: 45839 | H10: =IF(F10="Vivaio", DATE(2999, 12, 31), IF(F10="Standard", DATE(YEAR(G10)+1, MONTH(G10), DAY(G10)), IF(F10="Standard Inverno", DATE(2026, 7, 1), IF(OR(F10="Diritto 1+1", F10="Obbligo 1+1"), DATE(YEAR(G10)+2, MONTH(G10), DAY(G10)), IF(F10="Obbligo 1+2", DATE(YEAR(G10)+3, MONTH(G10), DAY(G10)), IF(OR(F10="Inverno Obbligo 1,5", F10="Inverno Diritto 0,5 + 1"), DATE(YEAR(G10)+1, MONTH(G10)+6, DAY(G10)), IF(F10="Inverno Obbligo 2,5", DATE(YEAR(G10)+2, MONTH(G10)+6, DAY(G10)), G10) ) ) ) ) ) ) -> 46204 | I10: Asta | J10: =VLOOKUP(A10,Asteriscati25!B:N,13,0) -> #N/A | L10: =VLOOKUP(B10,Rose!B:D,3,0) -> #REF! | M10: =VLOOKUP(B10,FVM_Asta2526!A:N,14,0) -> 142 | N10: =VLOOKUP(A10,FVM_update!B:N,13,0) -> 86 | O10: =VLOOKUP(B10,'FVM_1luglio-31luglio25'!D:Q,14,0) -> 110 | P10: =IFERROR(N10,O10) -> 86 | Q10: =IF(OR(F10="Standard",F10="Standard Inverno"),CEILING((M10/10),0.5), IF(OR(F10="Diritto 1+1",M10="Inverno Diritto 0,5 + 1"),CEILING((M10/10)*1.3,0.5), CEILING((M10/10)*1.15,0.5))) -> 14.5 | R10: =IF(I10="vivaio", 0.5, IF(OR(I10="asta", I10="Svincolato riconferma anno corrente", I10="vivaio", I10="promosso da vivaio"), Q10, IF(OR(I10="asta riparazione", I10="Svincolato obbligo anno precedente", I10="Svincolo pausa invernale"), MAX(0.5, CEILING(Q10 / 2, 0.5)), IF(OR(I10="ceduto in prestito", I10="acquisito in prestito", I10="acquistato tit definitivo", I10="Ceduto tit definitivo"),CEILING(Q10 * K10, 0.5), IF(I10="asteriscato", "inserire a mano", "")))) ) -> 14.5
A11: =VLOOKUP(B11,FVM_update!A:B,2,0) -> 22 | B11: DE ROON | C11: AS Intomatici | D11: =VLOOKUP(B11,FVM_update!A:F,6,0) -> Atalanta | E11: =VLOOKUP(B11,FVM_update!A:E,4,0) -> M;C | F11: Standard | G11: 45839 | H11: =IF(F11="Vivaio", DATE(2999, 12, 31), IF(F11="Standard", DATE(YEAR(G11)+1, MONTH(G11), DAY(G11)), IF(F11="Standard Inverno", DATE(2026, 7, 1), IF(OR(F11="Diritto 1+1", F11="Obbligo 1+1"), DATE(YEAR(G11)+2, MONTH(G11), DAY(G11)), IF(F11="Obbligo 1+2", DATE(YEAR(G11)+3, MONTH(G11), DAY(G11)), IF(OR(F11="Inverno Obbligo 1,5", F11="Inverno Diritto 0,5 + 1"), DATE(YEAR(G11)+1, MONTH(G11)+6, DAY(G11)), IF(F11="Inverno Obbligo 2,5", DATE(YEAR(G11)+2, MONTH(G11)+6, DAY(G11)), G11) ) ) ) ) ) ) -> 46204 | I11: Asta | J11: =VLOOKUP(A11,Asteriscati25!B:N,13,0) -> #N/A | L11: =VLOOKUP(B11,Rose!B:D,3,0) -> #REF! | M11: =VLOOKUP(B11,FVM_Asta2526!A:N,14,0) -> 37 | N11: =VLOOKUP(A11,FVM_update!B:N,13,0) -> 39 | O11: =VLOOKUP(B11,'FVM_1luglio-31luglio25'!D:Q,14,0) -> 32 | P11: =IFERROR(N11,O11) -> 39 | Q11: =IF(OR(F11="Standard",F11="Standard Inverno"),CEILING((M11/10),0.5), IF(OR(F11="Diritto 1+1",M11="Inverno Diritto 0,5 + 1"),CEILING((M11/10)*1.3,0.5), CEILING((M11/10)*1.15,0.5))) -> 4 | R11: =IF(I11="vivaio", 0.5, IF(OR(I11="asta", I11="Svincolato riconferma anno corrente", I11="vivaio", I11="promosso da vivaio"), Q11, IF(OR(I11="asta riparazione", I11="Svincolato obbligo anno precedente", I11="Svincolo pausa invernale"), MAX(0.5, CEILING(Q11 / 2, 0.5)), IF(OR(I11="ceduto in prestito", I11="acquisito in prestito", I11="acquistato tit definitivo", I11="Ceduto tit definitivo"),CEILING(Q11 * K11, 0.5), IF(I11="asteriscato", "inserire a mano", "")))) ) -> 4
A12: =VLOOKUP(B12,FVM_update!A:B,2,0) -> 2816 | B12: DI LORENZO | C12: AS Intomatici | D12: =VLOOKUP(B12,FVM_update!A:F,6,0) -> Napoli | E12: =VLOOKUP(B12,FVM_update!A:E,4,0) -> Dd;E | F12: Obbligo 1+2 | G12: 45839 | H12: =IF(F12="Vivaio", DATE(2999, 12, 31), IF(F12="Standard", DATE(YEAR(G12)+1, MONTH(G12), DAY(G12)), IF(F12="Standard Inverno", DATE(2026, 7, 1), IF(OR(F12="Diritto 1+1", F12="Obbligo 1+1"), DATE(YEAR(G12)+2, MONTH(G12), DAY(G12)), IF(F12="Obbligo 1+2", DATE(YEAR(G12)+3, MONTH(G12), DAY(G12)), IF(OR(F12="Inverno Obbligo 1,5", F12="Inverno Diritto 0,5 + 1"), DATE(YEAR(G12)+1, MONTH(G12)+6, DAY(G12)), IF(F12="Inverno Obbligo 2,5", DATE(YEAR(G12)+2, MONTH(G12)+6, DAY(G12)), G12) ) ) ) ) ) ) -> 46935 | I12: Asta | J12: =VLOOKUP(A12,Asteriscati25!B:N,13,0) -> #N/A | L12: =VLOOKUP(B12,Rose!B:D,3,0) -> #REF! | M12: =VLOOKUP(B12,FVM_Asta2526!A:N,14,0) -> 53 | N12: =VLOOKUP(A12,FVM_update!B:N,13,0) -> 37 | O12: =VLOOKUP(B12,'FVM_1luglio-31luglio25'!D:Q,14,0) -> 76 | P12: =IFERROR(N12,O12) -> 37 | Q12: =IF(OR(F12="Standard",F12="Standard Inverno"),CEILING((M12/10),0.5), IF(OR(F12="Diritto 1+1",M12="Inverno Diritto 0,5 + 1"),CEILING((M12/10)*1.3,0.5), CEILING((M12/10)*1.15,0.5))) -> 6.5 | R12: =IF(I12="vivaio", 0.5, IF(OR(I12="asta", I12="Svincolato riconferma anno corrente", I12="vivaio", I12="promosso da vivaio"), Q12, IF(OR(I12="asta riparazione", I12="Svincolato obbligo anno precedente", I12="Svincolo pausa invernale"), MAX(0.5, CEILING(Q12 / 2, 0.5)), IF(OR(I12="ceduto in prestito", I12="acquisito in prestito", I12="acquistato tit definitivo", I12="Ceduto tit definitivo"),CEILING(Q12 * K12, 0.5), IF(I12="asteriscato", "inserire a mano", "")))) ) -> 6.5
A13: =VLOOKUP(B13,FVM_update!A:B,2,0) -> 5851 | B13: DOIG | C13: AS Intomatici | D13: =VLOOKUP(B13,FVM_update!A:F,6,0) -> Sassuolo | E13: =VLOOKUP(B13,FVM_update!A:E,4,0) -> Ds;E | F13: Standard | G13: 45839 | H13: =IF(F13="Vivaio", DATE(2999, 12, 31), IF(F13="Standard", DATE(YEAR(G13)+1, MONTH(G13), DAY(G13)), IF(F13="Standard Inverno", DATE(2026, 7, 1), IF(OR(F13="Diritto 1+1", F13="Obbligo 1+1"), DATE(YEAR(G13)+2, MONTH(G13), DAY(G13)), IF(F13="Obbligo 1+2", DATE(YEAR(G13)+3, MONTH(G13), DAY(G13)), IF(OR(F13="Inverno Obbligo 1,5", F13="Inverno Diritto 0,5 + 1"), DATE(YEAR(G13)+1, MONTH(G13)+6, DAY(G13)), IF(F13="Inverno Obbligo 2,5", DATE(YEAR(G13)+2, MONTH(G13)+6, DAY(G13)), G13) ) ) ) ) ) ) -> 46204 | I13: Asta | J13: =VLOOKUP(A13,Asteriscati25!B:N,13,0) -> #N/A | L13: =VLOOKUP(B13,Rose!B:D,3,0) -> #REF! | M13: =VLOOKUP(B13,FVM_Asta2526!A:N,14,0) -> 17 | N13: =VLOOKUP(A13,FVM_update!B:N,13,0) -> 14 | O13: =VLOOKUP(B13,'FVM_1luglio-31luglio25'!D:Q,14,0) -> #N/A | P13: =IFERROR(N13,O13) -> 14 | Q13: =IF(OR(F13="Standard",F13="Standard Inverno"),CEILING((M13/10),0.5), IF(OR(F13="Diritto 1+1",M13="Inverno Diritto 0,5 + 1"),CEILING((M13/10)*1.3,0.5), CEILING((M13/10)*1.15,0.5))) -> 2 | R13: =IF(I13="vivaio", 0.5, IF(OR(I13="asta", I13="Svincolato riconferma anno corrente", I13="vivaio", I13="promosso da vivaio"), Q13, IF(OR(I13="asta riparazione", I13="Svincolato obbligo anno precedente", I13="Svincolo pausa invernale"), MAX(0.5, CEILING(Q13 / 2, 0.5)), IF(OR(I13="ceduto in prestito", I13="acquisito in prestito", I13="acquistato tit definitivo", I13="Ceduto tit definitivo"),CEILING(Q13 * K13, 0.5), IF(I13="asteriscato", "inserire a mano", "")))) ) -> 2
A14: =VLOOKUP(B14,FVM_update!A:B,2,0) -> 6047 | B14: EHIZIBUE | C14: AS Intomatici | D14: =VLOOKUP(B14,FVM_update!A:F,6,0) -> Udinese | E14: =VLOOKUP(B14,FVM_update!A:E,4,0) -> Dd;E | F14: Standard | G14: 45839 | H14: =IF(F14="Vivaio", DATE(2999, 12, 31), IF(F14="Standard", DATE(YEAR(G14)+1, MONTH(G14), DAY(G14)), IF(F14="Standard Inverno", DATE(2026, 7, 1), IF(OR(F14="Diritto 1+1", F14="Obbligo 1+1"), DATE(YEAR(G14)+2, MONTH(G14), DAY(G14)), IF(F14="Obbligo 1+2", DATE(YEAR(G14)+3, MONTH(G14), DAY(G14)), IF(OR(F14="Inverno Obbligo 1,5", F14="Inverno Diritto 0,5 + 1"), DATE(YEAR(G14)+1, MONTH(G14)+6, DAY(G14)), IF(F14="Inverno Obbligo 2,5", DATE(YEAR(G14)+2, MONTH(G14)+6, DAY(G14)), G14) ) ) ) ) ) ) -> 46204 | I14: Asta | J14: =VLOOKUP(A14,Asteriscati25!B:N,13,0) -> #N/A | L14: =VLOOKUP(B14,Rose!B:D,3,0) -> #REF! | M14: =VLOOKUP(B14,FVM_Asta2526!A:N,14,0) -> 15 | N14: =VLOOKUP(A14,FVM_update!B:N,13,0) -> 8 | O14: =VLOOKUP(B14,'FVM_1luglio-31luglio25'!D:Q,14,0) -> 9 | P14: =IFERROR(N14,O14) -> 8 | Q14: =IF(OR(F14="Standard",F14="Standard Inverno"),CEILING((M14/10),0.5), IF(OR(F14="Diritto 1+1",M14="Inverno Diritto 0,5 + 1"),CEILING((M14/10)*1.3,0.5), CEILING((M14/10)*1.15,0.5))) -> 1.5 | R14: =IF(I14="vivaio", 0.5, IF(OR(I14="asta", I14="Svincolato riconferma anno corrente", I14="vivaio", I14="promosso da vivaio"), Q14, IF(OR(I14="asta riparazione", I14="Svincolato obbligo anno precedente", I14="Svincolo pausa invernale"), MAX(0.5, CEILING(Q14 / 2, 0.5)), IF(OR(I14="ceduto in prestito", I14="acquisito in prestito", I14="acquistato tit definitivo", I14="Ceduto tit definitivo"),CEILING(Q14 * K14, 0.5), IF(I14="asteriscato", "inserire a mano", "")))) ) -> 1.5
A15: =VLOOKUP(B15,FVM_update!A:B,2,0) -> 4463 | B15: ESPOSITO SE. | C15: AS Intomatici | D15: =VLOOKUP(B15,FVM_update!A:F,6,0) -> Cagliari | E15: =VLOOKUP(B15,FVM_update!A:E,4,0) -> A | F15: Standard | G15: 45839 | H15: =IF(F15="Vivaio", DATE(2999, 12, 31), IF(F15="Standard", DATE(YEAR(G15)+1, MONTH(G15), DAY(G15)), IF(F15="Standard Inverno", DATE(2026, 7, 1), IF(OR(F15="Diritto 1+1", F15="Obbligo 1+1"), DATE(YEAR(G15)+2, MONTH(G15), DAY(G15)), IF(F15="Obbligo 1+2", DATE(YEAR(G15)+3, MONTH(G15), DAY(G15)), IF(OR(F15="Inverno Obbligo 1,5", F15="Inverno Diritto 0,5 + 1"), DATE(YEAR(G15)+1, MONTH(G15)+6, DAY(G15)), IF(F15="Inverno Obbligo 2,5", DATE(YEAR(G15)+2, MONTH(G15)+6, DAY(G15)), G15) ) ) ) ) ) ) -> 46204 | I15: Asta | J15: =VLOOKUP(A15,Asteriscati25!B:N,13,0) -> #N/A | L15: =VLOOKUP(B15,Rose!B:D,3,0) -> #REF! | M15: =VLOOKUP(B15,FVM_Asta2526!A:N,14,0) -> 66 | N15: =VLOOKUP(A15,FVM_update!B:N,13,0) -> 57 | O15: =VLOOKUP(B15,'FVM_1luglio-31luglio25'!D:Q,14,0) -> 26 | P15: =IFERROR(N15,O15) -> 57 | Q15: =IF(OR(F15="Standard",F15="Standard Inverno"),CEILING((M15/10),0.5), IF(OR(F15="Diritto 1+1",M15="Inverno Diritto 0,5 + 1"),CEILING((M15/10)*1.3,0.5), CEILING((M15/10)*1.15,0.5))) -> 7 | R15: =IF(I15="vivaio", 0.5, IF(OR(I15="asta", I15="Svincolato riconferma anno corrente", I15="vivaio", I15="promosso da vivaio"), Q15, IF(OR(I15="asta riparazione", I15="Svincolato obbligo anno precedente", I15="Svincolo pausa invernale"), MAX(0.5, CEILING(Q15 / 2, 0.5)), IF(OR(I15="ceduto in prestito", I15="acquisito in prestito", I15="acquistato tit definitivo", I15="Ceduto tit definitivo"),CEILING(Q15 * K15, 0.5), IF(I15="asteriscato", "inserire a mano", "")))) ) -> 7
A16: =VLOOKUP(B16,FVM_update!A:B,2,0) -> 6046 | B16: HIEN | C16: AS Intomatici | D16: =VLOOKUP(B16,FVM_update!A:F,6,0) -> Atalanta | E16: =VLOOKUP(B16,FVM_update!A:E,4,0) -> Dc | F16: Standard | G16: 45839 | H16: =IF(F16="Vivaio", DATE(2999, 12, 31), IF(F16="Standard", DATE(YEAR(G16)+1, MONTH(G16), DAY(G16)), IF(F16="Standard Inverno", DATE(2026, 7, 1), IF(OR(F16="Diritto 1+1", F16="Obbligo 1+1"), DATE(YEAR(G16)+2, MONTH(G16), DAY(G16)), IF(F16="Obbligo 1+2", DATE(YEAR(G16)+3, MONTH(G16), DAY(G16)), IF(OR(F16="Inverno Obbligo 1,5", F16="Inverno Diritto 0,5 + 1"), DATE(YEAR(G16)+1, MONTH(G16)+6, DAY(G16)), IF(F16="Inverno Obbligo 2,5", DATE(YEAR(G16)+2, MONTH(G16)+6, DAY(G16)), G16) ) ) ) ) ) ) -> 46204 | I16: Asta | J16: =VLOOKUP(A16,Asteriscati25!B:N,13,0) -> #N/A | L16: =VLOOKUP(B16,Rose!B:D,3,0) -> #REF! | M16: =VLOOKUP(B16,FVM_Asta2526!A:N,14,0) -> 34 | N16: =VLOOKUP(A16,FVM_update!B:N,13,0) -> 21 | O16: =VLOOKUP(B16,'FVM_1luglio-31luglio25'!D:Q,14,0) -> 20 | P16: =IFERROR(N16,O16) -> 21 | Q16: =IF(OR(F16="Standard",F16="Standard Inverno"),CEILING((M16/10),0.5), IF(OR(F16="Diritto 1+1",M16="Inverno Diritto 0,5 + 1"),CEILING((M16/10)*1.3,0.5), CEILING((M16/10)*1.15,0.5))) -> 3.5 | R16: =IF(I16="vivaio", 0.5, IF(OR(I16="asta", I16="Svincolato riconferma anno corrente", I16="vivaio", I16="promosso da vivaio"), Q16, IF(OR(I16="asta riparazione", I16="Svincolato obbligo anno precedente", I16="Svincolo pausa invernale"), MAX(0.5, CEILING(Q16 / 2, 0.5)), IF(OR(I16="ceduto in prestito", I16="acquisito in prestito", I16="acquistato tit definitivo", I16="Ceduto tit definitivo"),CEILING(Q16 * K16, 0.5), IF(I16="asteriscato", "inserire a mano", "")))) ) -> 3.5
A17: =VLOOKUP(B17,FVM_update!A:B,2,0) -> 5850 | B17: Lovric | C17: AS Intomatici | D17: =VLOOKUP(B17,FVM_update!A:F,6,0) -> Verona | E17: =VLOOKUP(B17,FVM_update!A:E,4,0) -> C | F17: =VLOOKUP(B17,'situazione contratti estate 24'!A:I,9,0) -> Obbligo 1+2 | G17: 45108 | H17: =IF(F17="Vivaio", DATE(2999, 12, 31), IF(F17="Standard", DATE(YEAR(G17)+1, MONTH(G17), DAY(G17)), IF(F17="Standard Inverno", DATE(2026, 7, 1), IF(OR(F17="Diritto 1+1", F17="Obbligo 1+1"), DATE(YEAR(G17)+2, MONTH(G17), DAY(G17)), IF(F17="Obbligo 1+2", DATE(YEAR(G17)+3, MONTH(G17), DAY(G17)), IF(OR(F17="Inverno Obbligo 1,5", F17="Inverno Diritto 0,5 + 1"), DATE(YEAR(G17)+1, MONTH(G17)+6, DAY(G17)), IF(F17="Inverno Obbligo 2,5", DATE(YEAR(G17)+2, MONTH(G17)+6, DAY(G17)), G17) ) ) ) ) ) ) -> 46204 | I17: Svincolato riconferma anno corrente | J17: =VLOOKUP(A17,Asteriscati25!B:N,13,0) -> #N/A | K17: 0 | L17: =VLOOKUP(B17,Rose!B:D,3,0) -> #REF! | M17: =VLOOKUP(B17,FVM_Asta2324!C:M,11,0) -> 53 | N17: =VLOOKUP(A17,FVM_update!B:N,13,0) -> 12 | O17: =VLOOKUP(B17,'FVM_1luglio-31luglio25'!D:Q,14,0) -> 22 | P17: =IFERROR(N17,O17) -> 12 | Q17: =IF(OR(F17="Standard",F17="Standard Inverno"),CEILING((M17/10),0.5), IF(OR(F17="Diritto 1+1",M17="Inverno Diritto 0,5 + 1"),CEILING((M17/10)*1.3,0.5), CEILING((M17/10)*1.15,0.5))) -> 6.5 | R17: =IF(I17="vivaio", 0.5, IF(OR(I17="asta", I17="Svincolato riconferma anno corrente", I17="vivaio", I17="promosso da vivaio"), Q17, IF(OR(I17="asta riparazione", I17="Svincolato obbligo anno precedente", I17="Svincolo pausa invernale"), MAX(0.5, CEILING(Q17 / 2, 0.5)), IF(OR(I17="ceduto in prestito", I17="acquisito in prestito", I17="acquistato tit definitivo", I17="Ceduto tit definitivo"),CEILING(Q17 * K17, 0.5), IF(I17="asteriscato", "inserire a mano", "")))) ) -> 6.5
A18: =VLOOKUP(B18,FVM_update!A:B,2,0) -> 6215 | B18: Lucca | C18: AS Intomatici | D18: =VLOOKUP(B18,FVM_update!A:F,6,0) -> Napoli | E18: =VLOOKUP(B18,FVM_update!A:E,4,0) -> Pc | F18: Obbligo 1+1 | G18: 45474 | H18: =IF(F18="Vivaio", DATE(2999, 12, 31), IF(F18="Standard", DATE(YEAR(G18)+1, MONTH(G18), DAY(G18)), IF(F18="Standard Inverno", DATE(2026, 7, 1), IF(OR(F18="Diritto 1+1", F18="Obbligo 1+1"), DATE(YEAR(G18)+2, MONTH(G18), DAY(G18)), IF(F18="Obbligo 1+2", DATE(YEAR(G18)+3, MONTH(G18), DAY(G18)), IF(OR(F18="Inverno Obbligo 1,5", F18="Inverno Diritto 0,5 + 1"), DATE(YEAR(G18)+1, MONTH(G18)+6, DAY(G18)), IF(F18="Inverno Obbligo 2,5", DATE(YEAR(G18)+2, MONTH(G18)+6, DAY(G18)), G18) ) ) ) ) ) ) -> 46204 | I18: Svincolato obbligo anno precedente | J18: =VLOOKUP(A18,Asteriscati25!B:N,13,0) -> #N/A | K18: 0 | L18: =VLOOKUP(B18,Rose!B:D,3,0) -> #REF! | M18: =VLOOKUP(B18,FVM_Asta2425!A:M,13,0) -> 68 | N18: =VLOOKUP(A18,#REF!,13,0) -> #REF! | O18: =VLOOKUP(B18,'FVM_1luglio-31luglio25'!D:Q,14,0) -> 78 | P18: =IFERROR(N18,O18) -> 78 | Q18: =IF(OR(F18="Standard",F18="Standard Inverno"),CEILING((M18/10),0.5), IF(OR(F18="Diritto 1+1",M18="Inverno Diritto 0,5 + 1"),CEILING((M18/10)*1.3,0.5), CEILING((M18/10)*1.15,0.5))) -> 8 | R18: =IF(OR(I18="asta", I18="Svincolato riconferma anno corrente", I18="vivaio"), Q18, IF(OR(I18="asta riparazione", I18="Svincolato obbligo anno precedente", I18="Svincolo pausa invernale"), MAX(0.5, CEILING(Q18 / 2, 0.5)), IF(OR(I18="ceduto in prestito", I18="acquisito in prestito", I18="acquistato tit definitivo", I18="Ceduto tit definitivo"),CEILING(Q18 * K18, 0.5), IF(I18="asteriscato", "inserire a mano", "")))) -> 4
A19: =VLOOKUP(B19,FVM_update!A:B,2,0) -> 6042 | B19: LUCUMì | C19: AS Intomatici | D19: =VLOOKUP(B19,FVM_update!A:F,6,0) -> Bologna | E19: =VLOOKUP(B19,FVM_update!A:E,4,0) -> Dc | F19: Standard | G19: 45839 | H19: =IF(F19="Vivaio", DATE(2999, 12, 31), IF(F19="Standard", DATE(YEAR(G19)+1, MONTH(G19), DAY(G19)), IF(F19="Standard Inverno", DATE(2026, 7, 1), IF(OR(F19="Diritto 1+1", F19="Obbligo 1+1"), DATE(YEAR(G19)+2, MONTH(G19), DAY(G19)), IF(F19="Obbligo 1+2", DATE(YEAR(G19)+3, MONTH(G19), DAY(G19)), IF(OR(F19="Inverno Obbligo 1,5", F19="Inverno Diritto 0,5 + 1"), DATE(YEAR(G19)+1, MONTH(G19)+6, DAY(G19)), IF(F19="Inverno Obbligo 2,5", DATE(YEAR(G19)+2, MONTH(G19)+6, DAY(G19)), G19) ) ) ) ) ) ) -> 46204 | I19: Asta | J19: =VLOOKUP(A19,Asteriscati25!B:N,13,0) -> #N/A | L19: =VLOOKUP(B19,Rose!B:D,3,0) -> #REF! | M19: =VLOOKUP(B19,FVM_Asta2526!A:N,14,0) -> 21 | N19: =VLOOKUP(A19,FVM_update!B:N,13,0) -> 12 | O19: =VLOOKUP(B19,'FVM_1luglio-31luglio25'!D:Q,14,0) -> #N/A | P19: =IFERROR(N19,O19) -> 12 | Q19: =IF(OR(F19="Standard",F19="Standard Inverno"),CEILING((M19/10),0.5), IF(OR(F19="Diritto 1+1",M19="Inverno Diritto 0,5 + 1"),CEILING((M19/10)*1.3,0.5), CEILING((M19/10)*1.15,0.5))) -> 2.5 | R19: =IF(I19="vivaio", 0.5, IF(OR(I19="asta", I19="Svincolato riconferma anno corrente", I19="vivaio", I19="promosso da vivaio"), Q19, IF(OR(I19="asta riparazione", I19="Svincolato obbligo anno precedente", I19="Svincolo pausa invernale"), MAX(0.5, CEILING(Q19 / 2, 0.5)), IF(OR(I19="ceduto in prestito", I19="acquisito in prestito", I19="acquistato tit definitivo", I19="Ceduto tit definitivo"),CEILING(Q19 * K19, 0.5), IF(I19="asteriscato", "inserire a mano", "")))) ) -> 2.5
A20: =VLOOKUP(B20,FVM_update!A:B,2,0) -> 2296 | B20: Mancini | C20: AS Intomatici | D20: =VLOOKUP(B20,FVM_update!A:F,6,0) -> Roma | E20: =VLOOKUP(B20,FVM_update!A:E,4,0) -> Dc | F20: Obbligo 1+1 | G20: 45474 | H20: =IF(F20="Vivaio", DATE(2999, 12, 31), IF(F20="Standard", DATE(YEAR(G20)+1, MONTH(G20), DAY(G20)), IF(F20="Standard Inverno", DATE(2026, 7, 1), IF(OR(F20="Diritto 1+1", F20="Obbligo 1+1"), DATE(YEAR(G20)+2, MONTH(G20), DAY(G20)), IF(F20="Obbligo 1+2", DATE(YEAR(G20)+3, MONTH(G20), DAY(G20)), IF(OR(F20="Inverno Obbligo 1,5", F20="Inverno Diritto 0,5 + 1"), DATE(YEAR(G20)+1, MONTH(G20)+6, DAY(G20)), IF(F20="Inverno Obbligo 2,5", DATE(YEAR(G20)+2, MONTH(G20)+6, DAY(G20)), G20) ) ) ) ) ) ) -> 46204 | I20: Ceduto in prestito | J20: =VLOOKUP(A20,Asteriscati25!B:N,13,0) -> #N/A | K20: 0 | L20: =VLOOKUP(B20,Rose!B:D,3,0) -> #REF! | M20: =VLOOKUP(B20,FVM_Asta2425!A:M,13,0) -> 26 | N20: =VLOOKUP(A20,FVM_update!B:N,13,0) -> 39 | O20: =VLOOKUP(B20,'FVM_1luglio-31luglio25'!D:Q,14,0) -> 27 | P20: =IFERROR(N20,O20) -> 39 | Q20: =IF(OR(F20="Standard",F20="Standard Inverno"),CEILING((M20/10),0.5), IF(OR(F20="Diritto 1+1",M20="Inverno Diritto 0,5 + 1"),CEILING((M20/10)*1.3,0.5), CEILING((M20/10)*1.15,0.5))) -> 3 | R20: =IF(I20="vivaio", 0.5, IF(OR(I20="asta", I20="Svincolato riconferma anno corrente", I20="vivaio", I20="promosso da vivaio"), Q20, IF(OR(I20="asta riparazione", I20="Svincolato obbligo anno precedente", I20="Svincolo pausa invernale"), MAX(0.5, CEILING(Q20 / 2, 0.5)), IF(OR(I20="ceduto in prestito", I20="acquisito in prestito", I20="acquistato tit definitivo", I20="Ceduto tit definitivo"),CEILING(Q20 * K20, 0.5), IF(I20="asteriscato", "inserire a mano", "")))) ) -> 0
A21: =VLOOKUP(B21,FVM_update!A:B,2,0) -> 4734 | B21: Miranda J. | C21: AS Intomatici | D21: =VLOOKUP(B21,FVM_update!A:F,6,0) -> Bologna | E21: =VLOOKUP(B21,FVM_update!A:E,4,0) -> Ds;E | F21: Diritto 1+1 | G21: 45474 | H21: =IF(F21="Vivaio", DATE(2999, 12, 31), IF(F21="Standard", DATE(YEAR(G21)+1, MONTH(G21), DAY(G21)), IF(F21="Standard Inverno", DATE(2026, 7, 1), IF(OR(F21="Diritto 1+1", F21="Obbligo 1+1"), DATE(YEAR(G21)+2, MONTH(G21), DAY(G21)), IF(F21="Obbligo 1+2", DATE(YEAR(G21)+3, MONTH(G21), DAY(G21)), IF(OR(F21="Inverno Obbligo 1,5", F21="Inverno Diritto 0,5 + 1"), DATE(YEAR(G21)+1, MONTH(G21)+6, DAY(G21)), IF(F21="Inverno Obbligo 2,5", DATE(YEAR(G21)+2, MONTH(G21)+6, DAY(G21)), G21) ) ) ) ) ) ) -> 46204 | I21: Asta | J21: =VLOOKUP(A21,Asteriscati25!B:N,13,0) -> #N/A | K21: 0 | L21: =VLOOKUP(B21,Rose!B:D,3,0) -> #REF! | M21: =VLOOKUP(B21,FVM_Asta2425!A:M,13,0) -> 16 | N21: =VLOOKUP(A21,FVM_update!B:N,13,0) -> 13 | O21: =VLOOKUP(B21,'FVM_1luglio-31luglio25'!D:Q,14,0) -> 21 | P21: =IFERROR(N21,O21) -> 13 | Q21: =IF(OR(F21="Standard",F21="Standard Inverno"),CEILING((M21/10),0.5), IF(OR(F21="Diritto 1+1",M21="Inverno Diritto 0,5 + 1"),CEILING((M21/10)*1.3,0.5), CEILING((M21/10)*1.15,0.5))) -> 2.5 | R21: =IF(I21="vivaio", 0.5, IF(OR(I21="asta", I21="Svincolato riconferma anno corrente", I21="vivaio", I21="promosso da vivaio"), Q21, IF(OR(I21="asta riparazione", I21="Svincolato obbligo anno precedente", I21="Svincolo pausa invernale"), MAX(0.5, CEILING(Q21 / 2, 0.5)), IF(OR(I21="ceduto in prestito", I21="acquisito in prestito", I21="acquistato tit definitivo", I21="Ceduto tit definitivo"),CEILING(Q21 * K21, 0.5), IF(I21="asteriscato", "inserire a mano", "")))) ) -> 2.5
A22: =VLOOKUP(B22,FVM_update!A:B,2,0) -> 2765 | B22: Odgaard | C22: AS Intomatici | D22: =VLOOKUP(B22,FVM_update!A:F,6,0) -> Bologna | E22: =VLOOKUP(B22,FVM_update!A:E,4,0) -> T;A | F22: Inverno Obbligo 2,5 | G22: 45689 | H22: =IF(F22="Vivaio", DATE(2999, 12, 31), IF(F22="Standard", DATE(YEAR(G22)+1, MONTH(G22), DAY(G22)), IF(F22="Standard Inverno", DATE(2026, 7, 1), IF(OR(F22="Diritto 1+1", F22="Obbligo 1+1"), DATE(YEAR(G22)+2, MONTH(G22), DAY(G22)), IF(F22="Obbligo 1+2", DATE(YEAR(G22)+3, MONTH(G22), DAY(G22)), IF(OR(F22="Inverno Obbligo 1,5", F22="Inverno Diritto 0,5 + 1"), DATE(YEAR(G22)+1, MONTH(G22)+6, DAY(G22)), IF(F22="Inverno Obbligo 2,5", DATE(YEAR(G22)+2, MONTH(G22)+6, DAY(G22)), G22) ) ) ) ) ) ) -> 46600 | I22: Asta | J22: =VLOOKUP(A22,Asteriscati25!B:N,13,0) -> #N/A | K22: 0 | L22: =VLOOKUP(B22,Rose!B:D,3,0) -> #REF! | M22: 55 | N22: =VLOOKUP(A22,FVM_update!B:N,13,0) -> 30 | O22: =VLOOKUP(B22,'FVM_1luglio-31luglio25'!D:Q,14,0) -> 28 | P22: =IFERROR(N22,O22) -> 30 | Q22: =IF(OR(F22="Standard",F22="Standard Inverno"),CEILING((M22/10),0.5), IF(OR(F22="Diritto 1+1",M22="Inverno Diritto 0,5 + 1"),CEILING((M22/10)*1.3,0.5), CEILING((M22/10)*1.15,0.5))) -> 6.5 | R22: =IF(I22="vivaio", 0.5, IF(OR(I22="asta", I22="Svincolato riconferma anno corrente", I22="vivaio", I22="promosso da vivaio"), Q22, IF(OR(I22="asta riparazione", I22="Svincolato obbligo anno precedente", I22="Svincolo pausa invernale"), MAX(0.5, CEILING(Q22 / 2, 0.5)), IF(OR(I22="ceduto in prestito", I22="acquisito in prestito", I22="acquistato tit definitivo", I22="Ceduto tit definitivo"),CEILING(Q22 * K22, 0.5), IF(I22="asteriscato", "inserire a mano", "")))) ) -> 6.5
A23: =VLOOKUP(B23,FVM_update!A:B,2,0) -> 2077 | B23: PASALIC | C23: AS Intomatici | D23: =VLOOKUP(B23,FVM_update!A:F,6,0) -> Atalanta | E23: =VLOOKUP(B23,FVM_update!A:E,4,0) -> C;T | F23: Diritto 1+1 | G23: 45839 | H23: =IF(F23="Vivaio", DATE(2999, 12, 31), IF(F23="Standard", DATE(YEAR(G23)+1, MONTH(G23), DAY(G23)), IF(F23="Standard Inverno", DATE(2026, 7, 1), IF(OR(F23="Diritto 1+1", F23="Obbligo 1+1"), DATE(YEAR(G23)+2, MONTH(G23), DAY(G23)), IF(F23="Obbligo 1+2", DATE(YEAR(G23)+3, MONTH(G23), DAY(G23)), IF(OR(F23="Inverno Obbligo 1,5", F23="Inverno Diritto 0,5 + 1"), DATE(YEAR(G23)+1, MONTH(G23)+6, DAY(G23)), IF(F23="Inverno Obbligo 2,5", DATE(YEAR(G23)+2, MONTH(G23)+6, DAY(G23)), G23) ) ) ) ) ) ) -> 46569 | I23: Asta | J23: =VLOOKUP(A23,Asteriscati25!B:N,13,0) -> #N/A | L23: =VLOOKUP(B23,Rose!B:D,3,0) -> #REF! | M23: =VLOOKUP(B23,FVM_Asta2526!A:N,14,0) -> 28 | N23: =VLOOKUP(A23,FVM_update!B:N,13,0) -> 21 | O23: =VLOOKUP(B23,'FVM_1luglio-31luglio25'!D:Q,14,0) -> 38 | P23: =IFERROR(N23,O23) -> 21 | Q23: =IF(OR(F23="Standard",F23="Standard Inverno"),CEILING((M23/10),0.5), IF(OR(F23="Diritto 1+1",M23="Inverno Diritto 0,5 + 1"),CEILING((M23/10)*1.3,0.5), CEILING((M23/10)*1.15,0.5))) -> 4 | R23: =IF(I23="vivaio", 0.5, IF(OR(I23="asta", I23="Svincolato riconferma anno corrente", I23="vivaio", I23="promosso da vivaio"), Q23, IF(OR(I23="asta riparazione", I23="Svincolato obbligo anno precedente", I23="Svincolo pausa invernale"), MAX(0.5, CEILING(Q23 / 2, 0.5)), IF(OR(I23="ceduto in prestito", I23="acquisito in prestito", I23="acquistato tit definitivo", I23="Ceduto tit definitivo"),CEILING(Q23 * K23, 0.5), IF(I23="asteriscato", "inserire a mano", "")))) ) -> 4
A24: =VLOOKUP(B24,FVM_update!A:B,2,0) -> 5603 | B24: PONGRACIC | C24: AS Intomatici | D24: =VLOOKUP(B24,FVM_update!A:F,6,0) -> Fiorentina | E24: =VLOOKUP(B24,FVM_update!A:E,4,0) -> Dc | F24: Standard | G24: 45839 | H24: =IF(F24="Vivaio", DATE(2999, 12, 31), IF(F24="Standard", DATE(YEAR(G24)+1, MONTH(G24), DAY(G24)), IF(F24="Standard Inverno", DATE(2026, 7, 1), IF(OR(F24="Diritto 1+1", F24="Obbligo 1+1"), DATE(YEAR(G24)+2, MONTH(G24), DAY(G24)), IF(F24="Obbligo 1+2", DATE(YEAR(G24)+3, MONTH(G24), DAY(G24)), IF(OR(F24="Inverno Obbligo 1,5", F24="Inverno Diritto 0,5 + 1"), DATE(YEAR(G24)+1, MONTH(G24)+6, DAY(G24)), IF(F24="Inverno Obbligo 2,5", DATE(YEAR(G24)+2, MONTH(G24)+6, DAY(G24)), G24) ) ) ) ) ) ) -> 46204 | I24: Asta | J24: =VLOOKUP(A24,Asteriscati25!B:N,13,0) -> #N/A | L24: =VLOOKUP(B24,Rose!B:D,3,0) -> #REF! | M24: =VLOOKUP(B24,FVM_Asta2526!A:N,14,0) -> 16 | N24: =VLOOKUP(A24,FVM_update!B:N,13,0) -> 12 | O24: =VLOOKUP(B24,'FVM_1luglio-31luglio25'!D:Q,14,0) -> 16 | P24: =IFERROR(N24,O24) -> 12 | Q24: =IF(OR(F24="Standard",F24="Standard Inverno"),CEILING((M24/10),0.5), IF(OR(F24="Diritto 1+1",M24="Inverno Diritto 0,5 + 1"),CEILING((M24/10)*1.3,0.5), CEILING((M24/10)*1.15,0.5))) -> 2 | R24: =IF(I24="vivaio", 0.5, IF(OR(I24="asta", I24="Svincolato riconferma anno corrente", I24="vivaio", I24="promosso da vivaio"), Q24, IF(OR(I24="asta riparazione", I24="Svincolato obbligo anno precedente", I24="Svincolo pausa invernale"), MAX(0.5, CEILING(Q24 / 2, 0.5)), IF(OR(I24="ceduto in prestito", I24="acquisito in prestito", I24="acquistato tit definitivo", I24="Ceduto tit definitivo"),CEILING(Q24 * K24, 0.5), IF(I24="asteriscato", "inserire a mano", "")))) ) -> 2
A25: =VLOOKUP(B25,FVM_update!A:B,2,0) -> 4378 | B25: RANIERI L. | C25: AS Intomatici | D25: =VLOOKUP(B25,FVM_update!A:F,6,0) -> Fiorentina | E25: =VLOOKUP(B25,FVM_update!A:E,4,0) -> Ds;Dc | F25: Standard | G25: 45839 | H25: =IF(F25="Vivaio", DATE(2999, 12, 31), IF(F25="Standard", DATE(YEAR(G25)+1, MONTH(G25), DAY(G25)), IF(F25="Standard Inverno", DATE(2026, 7, 1), IF(OR(F25="Diritto 1+1", F25="Obbligo 1+1"), DATE(YEAR(G25)+2, MONTH(G25), DAY(G25)), IF(F25="Obbligo 1+2", DATE(YEAR(G25)+3, MONTH(G25), DAY(G25)), IF(OR(F25="Inverno Obbligo 1,5", F25="Inverno Diritto 0,5 + 1"), DATE(YEAR(G25)+1, MONTH(G25)+6, DAY(G25)), IF(F25="Inverno Obbligo 2,5", DATE(YEAR(G25)+2, MONTH(G25)+6, DAY(G25)), G25) ) ) ) ) ) ) -> 46204 | I25: Asta | J25: =VLOOKUP(A25,Asteriscati25!B:N,13,0) -> #N/A | L25: =VLOOKUP(B25,Rose!B:D,3,0) -> #REF! | M25: =VLOOKUP(B25,FVM_Asta2526!A:N,14,0) -> 17 | N25: =VLOOKUP(A25,FVM_update!B:N,13,0) -> 12 | O25: =VLOOKUP(B25,'FVM_1luglio-31luglio25'!D:Q,14,0) -> 16 | P25: =IFERROR(N25,O25) -> 12 | Q25: =IF(OR(F25="Standard",F25="Standard Inverno"),CEILING((M25/10),0.5), IF(OR(F25="Diritto 1+1",M25="Inverno Diritto 0,5 + 1"),CEILING((M25/10)*1.3,0.5), CEILING((M25/10)*1.15,0.5))) -> 2 | R25: =IF(I25="vivaio", 0.5, IF(OR(I25="asta", I25="Svincolato riconferma anno corrente", I25="vivaio", I25="promosso da vivaio"), Q25, IF(OR(I25="asta riparazione", I25="Svincolato obbligo anno precedente", I25="Svincolo pausa invernale"), MAX(0.5, CEILING(Q25 / 2, 0.5)), IF(OR(I25="ceduto in prestito", I25="acquisito in prestito", I25="acquistato tit definitivo", I25="Ceduto tit definitivo"),CEILING(Q25 * K25, 0.5), IF(I25="asteriscato", "inserire a mano", "")))) ) -> 2
A26: =VLOOKUP(B26,FVM_update!A:B,2,0) -> 2722 | B26: RAVAGLIA F. | C26: AS Intomatici | D26: =VLOOKUP(B26,FVM_update!A:F,6,0) -> Bologna | E26: =VLOOKUP(B26,FVM_update!A:E,4,0) -> Por | F26: Standard | G26: 45839 | H26: =IF(F26="Vivaio", DATE(2999, 12, 31), IF(F26="Standard", DATE(YEAR(G26)+1, MONTH(G26), DAY(G26)), IF(F26="Standard Inverno", DATE(2026, 7, 1), IF(OR(F26="Diritto 1+1", F26="Obbligo 1+1"), DATE(YEAR(G26)+2, MONTH(G26), DAY(G26)), IF(F26="Obbligo 1+2", DATE(YEAR(G26)+3, MONTH(G26), DAY(G26)), IF(OR(F26="Inverno Obbligo 1,5", F26="Inverno Diritto 0,5 + 1"), DATE(YEAR(G26)+1, MONTH(G26)+6, DAY(G26)), IF(F26="Inverno Obbligo 2,5", DATE(YEAR(G26)+2, MONTH(G26)+6, DAY(G26)), G26) ) ) ) ) ) ) -> 46204 | I26: Asta | J26: =VLOOKUP(A26,Asteriscati25!B:N,13,0) -> #N/A | K26: 0 | L26: =VLOOKUP(B26,Rose!B:D,3,0) -> #REF! | M26: =VLOOKUP(B26,FVM_Asta2526!A:N,14,0) -> 5 | N26: =VLOOKUP(A26,FVM_update!B:N,13,0) -> 8 | O26: =VLOOKUP(B26,'FVM_1luglio-31luglio25'!D:Q,14,0) -> 1 | P26: =IFERROR(N26,O26) -> 8 | Q26: =IF(OR(F26="Standard",F26="Standard Inverno"),CEILING((M26/10),0.5), IF(OR(F26="Diritto 1+1",M26="Inverno Diritto 0,5 + 1"),CEILING((M26/10)*1.3,0.5), CEILING((M26/10)*1.15,0.5))) -> 0.5 | R26: =IF(I26="vivaio", 0.5, IF(OR(I26="asta", I26="Svincolato riconferma anno corrente", I26="vivaio", I26="promosso da vivaio"), Q26, IF(OR(I26="asta riparazione", I26="Svincolato obbligo anno precedente", I26="Svincolo pausa invernale"), MAX(0.5, CEILING(Q26 / 2, 0.5)), IF(OR(I26="ceduto in prestito", I26="acquisito in prestito", I26="acquistato tit definitivo", I26="Ceduto tit definitivo"),CEILING(Q26 * K26, 0.5), IF(I26="asteriscato", "inserire a mano", "")))) ) -> 0.5
A27: =VLOOKUP(B27,FVM_update!A:B,2,0) -> 5453 | B27: Ricci S. | C27: AS Intomatici | D27: =VLOOKUP(B27,FVM_update!A:F,6,0) -> Milan | E27: =VLOOKUP(B27,FVM_update!A:E,4,0) -> M;C | F27: =VLOOKUP(B27,'situazione contratti estate 24'!A:I,9,0) -> Obbligo 1+2 | G27: 45108 | H27: =IF(F27="Vivaio", DATE(2999, 12, 31), IF(F27="Standard", DATE(YEAR(G27)+1, MONTH(G27), DAY(G27)), IF(F27="Standard Inverno", DATE(2026, 7, 1), IF(OR(F27="Diritto 1+1", F27="Obbligo 1+1"), DATE(YEAR(G27)+2, MONTH(G27), DAY(G27)), IF(F27="Obbligo 1+2", DATE(YEAR(G27)+3, MONTH(G27), DAY(G27)), IF(OR(F27="Inverno Obbligo 1,5", F27="Inverno Diritto 0,5 + 1"), DATE(YEAR(G27)+1, MONTH(G27)+6, DAY(G27)), IF(F27="Inverno Obbligo 2,5", DATE(YEAR(G27)+2, MONTH(G27)+6, DAY(G27)), G27) ) ) ) ) ) ) -> 46204 | I27: Asta | J27: =VLOOKUP(A27,Asteriscati25!B:N,13,0) -> #N/A | K27: 0 | L27: =VLOOKUP(B27,Rose!B:D,3,0) -> #REF! | M27: =VLOOKUP(B27,FVM_Asta2324!C:M,11,0) -> 28 | N27: =VLOOKUP(A27,FVM_update!B:N,13,0) -> 16 | O27: =VLOOKUP(B27,'FVM_1luglio-31luglio25'!D:Q,14,0) -> 22 | P27: =IFERROR(N27,O27) -> 16 | Q27: =IF(OR(F27="Standard",F27="Standard Inverno"),CEILING((M27/10),0.5), IF(OR(F27="Diritto 1+1",M27="Inverno Diritto 0,5 + 1"),CEILING((M27/10)*1.3,0.5), CEILING((M27/10)*1.15,0.5))) -> 3.5 | R27: =IF(I27="vivaio", 0.5, IF(OR(I27="asta", I27="Svincolato riconferma anno corrente", I27="vivaio", I27="promosso da vivaio"), Q27, IF(OR(I27="asta riparazione", I27="Svincolato obbligo anno precedente", I27="Svincolo pausa invernale"), MAX(0.5, CEILING(Q27 / 2, 0.5)), IF(OR(I27="ceduto in prestito", I27="acquisito in prestito", I27="acquistato tit definitivo", I27="Ceduto tit definitivo"),CEILING(Q27 * K27, 0.5), IF(I27="asteriscato", "inserire a mano", "")))) ) -> 3.5
A28: =VLOOKUP(B28,FVM_update!A:B,2,0) -> 4892 | B28: SAELEMAEKERS | C28: AS Intomatici | D28: =VLOOKUP(B28,FVM_update!A:F,6,0) -> Milan | E28: =VLOOKUP(B28,FVM_update!A:E,4,0) -> E;W | F28: Diritto 1+1 | G28: 45839 | H28: =IF(F28="Vivaio", DATE(2999, 12, 31), IF(F28="Standard", DATE(YEAR(G28)+1, MONTH(G28), DAY(G28)), IF(F28="Standard Inverno", DATE(2026, 7, 1), IF(OR(F28="Diritto 1+1", F28="Obbligo 1+1"), DATE(YEAR(G28)+2, MONTH(G28), DAY(G28)), IF(F28="Obbligo 1+2", DATE(YEAR(G28)+3, MONTH(G28), DAY(G28)), IF(OR(F28="Inverno Obbligo 1,5", F28="Inverno Diritto 0,5 + 1"), DATE(YEAR(G28)+1, MONTH(G28)+6, DAY(G28)), IF(F28="Inverno Obbligo 2,5", DATE(YEAR(G28)+2, MONTH(G28)+6, DAY(G28)), G28) ) ) ) ) ) ) -> 46569 | I28: Asta | J28: =VLOOKUP(A28,Asteriscati25!B:N,13,0) -> #N/A | L28: =VLOOKUP(B28,Rose!B:D,3,0) -> #REF! | M28: =VLOOKUP(B28,FVM_Asta2526!A:N,14,0) -> 43 | N28: =VLOOKUP(A28,FVM_update!B:N,13,0) -> 89 | O28: =VLOOKUP(B28,'FVM_1luglio-31luglio25'!D:Q,14,0) -> 37 | P28: =IFERROR(N28,O28) -> 89 | Q28: =IF(OR(F28="Standard",F28="Standard Inverno"),CEILING((M28/10),0.5), IF(OR(F28="Diritto 1+1",M28="Inverno Diritto 0,5 + 1"),CEILING((M28/10)*1.3,0.5), CEILING((M28/10)*1.15,0.5))) -> 6 | R28: =IF(I28="vivaio", 0.5, IF(OR(I28="asta", I28="Svincolato riconferma anno corrente", I28="vivaio", I28="promosso da vivaio"), Q28, IF(OR(I28="asta riparazione", I28="Svincolato obbligo anno precedente", I28="Svincolo pausa invernale"), MAX(0.5, CEILING(Q28 / 2, 0.5)), IF(OR(I28="ceduto in prestito", I28="acquisito in prestito", I28="acquistato tit definitivo", I28="Ceduto tit definitivo"),CEILING(Q28 * K28, 0.5), IF(I28="asteriscato", "inserire a mano", "")))) ) -> 6
A29: =VLOOKUP(B29,FVM_update!A:B,2,0) -> 6523 | B29: Samooja | C29: AS Intomatici | D29: =VLOOKUP(B29,FVM_update!A:F,6,0) -> Lecce | E29: =VLOOKUP(B29,FVM_update!A:E,4,0) -> Por | F29: Vivaio | G29: 45474 | H29: =IF(F29="Vivaio", DATE(2999, 12, 31), IF(F29="Standard", DATE(YEAR(G29)+1, MONTH(G29), DAY(G29)), IF(F29="Standard Inverno", DATE(2026, 7, 1), IF(OR(F29="Diritto 1+1", F29="Obbligo 1+1"), DATE(YEAR(G29)+2, MONTH(G29), DAY(G29)), IF(F29="Obbligo 1+2", DATE(YEAR(G29)+3, MONTH(G29), DAY(G29)), IF(OR(F29="Inverno Obbligo 1,5", F29="Inverno Diritto 0,5 + 1"), DATE(YEAR(G29)+1, MONTH(G29)+6, DAY(G29)), IF(F29="Inverno Obbligo 2,5", DATE(YEAR(G29)+2, MONTH(G29)+6, DAY(G29)), G29) ) ) ) ) ) ) -> 401768 | I29: Vivaio | J29: =VLOOKUP(A29,Asteriscati25!B:N,13,0) -> #N/A | K29: 0 | L29: =VLOOKUP(B29,Rose!B:D,3,0) -> #REF! | M29: =VLOOKUP(B29,FVM_Asta2425!A:M,13,0) -> 1 | N29: =VLOOKUP(A29,FVM_update!B:N,13,0) -> 1 | O29: =VLOOKUP(B29,'FVM_1luglio-31luglio25'!D:Q,14,0) -> 1 | P29: =IFERROR(N29,O29) -> 1 | Q29: =IF(OR(F29="Standard",F29="Standard Inverno"),CEILING((M29/10),0.5), IF(OR(F29="Diritto 1+1",M29="Inverno Diritto 0,5 + 1"),CEILING((M29/10)*1.3,0.5), CEILING((M29/10)*1.15,0.5))) -> 0.5 | R29: =IF(I29="vivaio", 0.5, IF(OR(I29="asta", I29="Svincolato riconferma anno corrente", I29="vivaio", I29="promosso da vivaio"), Q29, IF(OR(I29="asta riparazione", I29="Svincolato obbligo anno precedente", I29="Svincolo pausa invernale"), MAX(0.5, CEILING(Q29 / 2, 0.5)), IF(OR(I29="ceduto in prestito", I29="acquisito in prestito", I29="acquistato tit definitivo", I29="Ceduto tit definitivo"),CEILING(Q29 * K29, 0.5), IF(I29="asteriscato", "inserire a mano", "")))) ) -> 0.5
A30: =VLOOKUP(B30,FVM_update!A:B,2,0) -> 133 | B30: SKORUPSKI | C30: AS Intomatici | D30: =VLOOKUP(B30,FVM_update!A:F,6,0) -> Bologna | E30: =VLOOKUP(B30,FVM_update!A:E,4,0) -> Por | F30: Obbligo 1+2 | G30: 45839 | H30: =IF(F30="Vivaio", DATE(2999, 12, 31), IF(F30="Standard", DATE(YEAR(G30)+1, MONTH(G30), DAY(G30)), IF(F30="Standard Inverno", DATE(2026, 7, 1), IF(OR(F30="Diritto 1+1", F30="Obbligo 1+1"), DATE(YEAR(G30)+2, MONTH(G30), DAY(G30)), IF(F30="Obbligo 1+2", DATE(YEAR(G30)+3, MONTH(G30), DAY(G30)), IF(OR(F30="Inverno Obbligo 1,5", F30="Inverno Diritto 0,5 + 1"), DATE(YEAR(G30)+1, MONTH(G30)+6, DAY(G30)), IF(F30="Inverno Obbligo 2,5", DATE(YEAR(G30)+2, MONTH(G30)+6, DAY(G30)), G30) ) ) ) ) ) ) -> 46935 | I30: Asta | J30: =VLOOKUP(A30,Asteriscati25!B:N,13,0) -> #N/A | L30: =VLOOKUP(B30,Rose!B:D,3,0) -> #REF! | M30: =VLOOKUP(B30,FVM_Asta2526!A:N,14,0) -> 50 | N30: =VLOOKUP(A30,FVM_update!B:N,13,0) -> 10 | O30: =VLOOKUP(B30,'FVM_1luglio-31luglio25'!D:Q,14,0) -> 44 | P30: =IFERROR(N30,O30) -> 10 | Q30: =IF(OR(F30="Standard",F30="Standard Inverno"),CEILING((M30/10),0.5), IF(OR(F30="Diritto 1+1",M30="Inverno Diritto 0,5 + 1"),CEILING((M30/10)*1.3,0.5), CEILING((M30/10)*1.15,0.5))) -> 6 | R30: =IF(I30="vivaio", 0.5, IF(OR(I30="asta", I30="Svincolato riconferma anno corrente", I30="vivaio", I30="promosso da vivaio"), Q30, IF(OR(I30="asta riparazione", I30="Svincolato obbligo anno precedente", I30="Svincolo pausa invernale"), MAX(0.5, CEILING(Q30 / 2, 0.5)), IF(OR(I30="ceduto in prestito", I30="acquisito in prestito", I30="acquistato tit definitivo", I30="Ceduto tit definitivo"),CEILING(Q30 * K30, 0.5), IF(I30="asteriscato", "inserire a mano", "")))) ) -> 6
A31: =VLOOKUP(B31,FVM_update!A:B,2,0) -> 5844 | B31: THORSTVEDT | C31: AS Intomatici | D31: =VLOOKUP(B31,FVM_update!A:F,6,0) -> Sassuolo | E31: =VLOOKUP(B31,FVM_update!A:E,4,0) -> C;T | F31: Standard | G31: 45839 | H31: =IF(F31="Vivaio", DATE(2999, 12, 31), IF(F31="Standard", DATE(YEAR(G31)+1, MONTH(G31), DAY(G31)), IF(F31="Standard Inverno", DATE(2026, 7, 1), IF(OR(F31="Diritto 1+1", F31="Obbligo 1+1"), DATE(YEAR(G31)+2, MONTH(G31), DAY(G31)), IF(F31="Obbligo 1+2", DATE(YEAR(G31)+3, MONTH(G31), DAY(G31)), IF(OR(F31="Inverno Obbligo 1,5", F31="Inverno Diritto 0,5 + 1"), DATE(YEAR(G31)+1, MONTH(G31)+6, DAY(G31)), IF(F31="Inverno Obbligo 2,5", DATE(YEAR(G31)+2, MONTH(G31)+6, DAY(G31)), G31) ) ) ) ) ) ) -> 46204 | I31: Asta | J31: =VLOOKUP(A31,Asteriscati25!B:N,13,0) -> #N/A | L31: =VLOOKUP(B31,Rose!B:D,3,0) -> #REF! | M31: =VLOOKUP(B31,FVM_Asta2526!A:N,14,0) -> 22 | N31: =VLOOKUP(A31,FVM_update!B:N,13,0) -> 25 | O31: =VLOOKUP(B31,'FVM_1luglio-31luglio25'!D:Q,14,0) -> #N/A | P31: =IFERROR(N31,O31) -> 25 | Q31: =IF(OR(F31="Standard",F31="Standard Inverno"),CEILING((M31/10),0.5), IF(OR(F31="Diritto 1+1",M31="Inverno Diritto 0,5 + 1"),CEILING((M31/10)*1.3,0.5), CEILING((M31/10)*1.15,0.5))) -> 2.5 | R31: =IF(I31="vivaio", 0.5, IF(OR(I31="asta", I31="Svincolato riconferma anno corrente", I31="vivaio", I31="promosso da vivaio"), Q31, IF(OR(I31="asta riparazione", I31="Svincolato obbligo anno precedente", I31="Svincolo pausa invernale"), MAX(0.5, CEILING(Q31 / 2, 0.5)), IF(OR(I31="ceduto in prestito", I31="acquisito in prestito", I31="acquistato tit definitivo", I31="Ceduto tit definitivo"),CEILING(Q31 * K31, 0.5), IF(I31="asteriscato", "inserire a mano", "")))) ) -> 2.5
A32: =VLOOKUP(B32,FVM_update!A:B,2,0) -> 2841 | B32: VLAHOVIC | C32: AS Intomatici | D32: =VLOOKUP(B32,FVM_update!A:F,6,0) -> Juventus | E32: =VLOOKUP(B32,FVM_update!A:E,4,0) -> Pc | F32: Standard | G32: 45839 | H32: =IF(F32="Vivaio", DATE(2999, 12, 31), IF(F32="Standard", DATE(YEAR(G32)+1, MONTH(G32), DAY(G32)), IF(F32="Standard Inverno", DATE(2026, 7, 1), IF(OR(F32="Diritto 1+1", F32="Obbligo 1+1"), DATE(YEAR(G32)+2, MONTH(G32), DAY(G32)), IF(F32="Obbligo 1+2", DATE(YEAR(G32)+3, MONTH(G32), DAY(G32)), IF(OR(F32="Inverno Obbligo 1,5", F32="Inverno Diritto 0,5 + 1"), DATE(YEAR(G32)+1, MONTH(G32)+6, DAY(G32)), IF(F32="Inverno Obbligo 2,5", DATE(YEAR(G32)+2, MONTH(G32)+6, DAY(G32)), G32) ) ) ) ) ) ) -> 46204 | I32: Svincolo pausa invernale | J32: =VLOOKUP(A32,Asteriscati25!B:N,13,0) -> #N/A | L32: =VLOOKUP(B32,Rose!B:D,3,0) -> #REF! | M32: =VLOOKUP(B32,FVM_Asta2526!A:N,14,0) -> 126 | N32: =VLOOKUP(A32,FVM_update!B:N,13,0) -> 47 | O32: =VLOOKUP(B32,'FVM_1luglio-31luglio25'!D:Q,14,0) -> 261 | P32: =IFERROR(N32,O32) -> 47 | Q32: =IF(OR(F32="Standard",F32="Standard Inverno"),CEILING((M32/10),0.5), IF(OR(F32="Diritto 1+1",M32="Inverno Diritto 0,5 + 1"),CEILING((M32/10)*1.3,0.5), CEILING((M32/10)*1.15,0.5))) -> 13 | R32: =IF(I32="vivaio", 0.5, IF(OR(I32="asta", I32="Svincolato riconferma anno corrente", I32="vivaio", I32="promosso da vivaio"), Q32, IF(OR(I32="asta riparazione", I32="Svincolato obbligo anno precedente", I32="Svincolo pausa invernale"), MAX(0.5, CEILING(Q32 / 2, 0.5)), IF(OR(I32="ceduto in prestito", I32="acquisito in prestito", I32="acquistato tit definitivo", I32="Ceduto tit definitivo"),CEILING(Q32 * K32, 0.5), IF(I32="asteriscato", "inserire a mano", "")))) ) -> 6.5
A33: =VLOOKUP(B33,FVM_update!A:B,2,0) -> 5422 | B33: ZALEWSKI | C33: AS Intomatici | D33: =VLOOKUP(B33,FVM_update!A:F,6,0) -> Atalanta | E33: =VLOOKUP(B33,FVM_update!A:E,4,0) -> E;W | F33: Obbligo 1+2 | G33: 45839 | H33: =IF(F33="Vivaio", DATE(2999, 12, 31), IF(F33="Standard", DATE(YEAR(G33)+1, MONTH(G33), DAY(G33)), IF(F33="Standard Inverno", DATE(2026, 7, 1), IF(OR(F33="Diritto 1+1", F33="Obbligo 1+1"), DATE(YEAR(G33)+2, MONTH(G33), DAY(G33)), IF(F33="Obbligo 1+2", DATE(YEAR(G33)+3, MONTH(G33), DAY(G33)), IF(OR(F33="Inverno Obbligo 1,5", F33="Inverno Diritto 0,5 + 1"), DATE(YEAR(G33)+1, MONTH(G33)+6, DAY(G33)), IF(F33="Inverno Obbligo 2,5", DATE(YEAR(G33)+2, MONTH(G33)+6, DAY(G33)), G33) ) ) ) ) ) ) -> 46935 | I33: Asta | J33: =VLOOKUP(A33,Asteriscati25!B:N,13,0) -> #N/A | L33: =VLOOKUP(B33,Rose!B:D,3,0) -> #REF! | M33: =VLOOKUP(B33,FVM_Asta2526!A:N,14,0) -> 28 | N33: =VLOOKUP(A33,FVM_update!B:N,13,0) -> 24 | O33: =VLOOKUP(B33,'FVM_1luglio-31luglio25'!D:Q,14,0) -> 9 | P33: =IFERROR(N33,O33) -> 24 | Q33: =IF(OR(F33="Standard",F33="Standard Inverno"),CEILING((M33/10),0.5), IF(OR(F33="Diritto 1+1",M33="Inverno Diritto 0,5 + 1"),CEILING((M33/10)*1.3,0.5), CEILING((M33/10)*1.15,0.5))) -> 3.5 | R33: =IF(I33="vivaio", 0.5, IF(OR(I33="asta", I33="Svincolato riconferma anno corrente", I33="vivaio", I33="promosso da vivaio"), Q33, IF(OR(I33="asta riparazione", I33="Svincolato obbligo anno precedente", I33="Svincolo pausa invernale"), MAX(0.5, CEILING(Q33 / 2, 0.5)), IF(OR(I33="ceduto in prestito", I33="acquisito in prestito", I33="acquistato tit definitivo", I33="Ceduto tit definitivo"),CEILING(Q33 * K33, 0.5), IF(I33="asteriscato", "inserire a mano", "")))) ) -> 3.5
A34: =VLOOKUP(B34,FVM_update!A:B,2,0) -> 4461 | B34: ZAPPA | C34: AS Intomatici | D34: =VLOOKUP(B34,FVM_update!A:F,6,0) -> Cagliari | E34: =VLOOKUP(B34,FVM_update!A:E,4,0) -> B;Dd;E | F34: Standard | G34: 45839 | H34: =IF(F34="Vivaio", DATE(2999, 12, 31), IF(F34="Standard", DATE(YEAR(G34)+1, MONTH(G34), DAY(G34)), IF(F34="Standard Inverno", DATE(2026, 7, 1), IF(OR(F34="Diritto 1+1", F34="Obbligo 1+1"), DATE(YEAR(G34)+2, MONTH(G34), DAY(G34)), IF(F34="Obbligo 1+2", DATE(YEAR(G34)+3, MONTH(G34), DAY(G34)), IF(OR(F34="Inverno Obbligo 1,5", F34="Inverno Diritto 0,5 + 1"), DATE(YEAR(G34)+1, MONTH(G34)+6, DAY(G34)), IF(F34="Inverno Obbligo 2,5", DATE(YEAR(G34)+2, MONTH(G34)+6, DAY(G34)), G34) ) ) ) ) ) ) -> 46204 | I34: Asta | J34: =VLOOKUP(A34,Asteriscati25!B:N,13,0) -> #N/A | L34: =VLOOKUP(B34,Rose!B:D,3,0) -> #REF! | M34: =VLOOKUP(B34,FVM_Asta2526!A:N,14,0) -> 16 | N34: =VLOOKUP(A34,FVM_update!B:N,13,0) -> 15 | O34: =VLOOKUP(B34,'FVM_1luglio-31luglio25'!D:Q,14,0) -> 15 | P34: =IFERROR(N34,O34) -> 15 | Q34: =IF(OR(F34="Standard",F34="Standard Inverno"),CEILING((M34/10),0.5), IF(OR(F34="Diritto 1+1",M34="Inverno Diritto 0,5 + 1"),CEILING((M34/10)*1.3,0.5), CEILING((M34/10)*1.15,0.5))) -> 2 | R34: =IF(I34="vivaio", 0.5, IF(OR(I34="asta", I34="Svincolato riconferma anno corrente", I34="vivaio", I34="promosso da vivaio"), Q34, IF(OR(I34="asta riparazione", I34="Svincolato obbligo anno precedente", I34="Svincolo pausa invernale"), MAX(0.5, CEILING(Q34 / 2, 0.5)), IF(OR(I34="ceduto in prestito", I34="acquisito in prestito", I34="acquistato tit definitivo", I34="Ceduto tit definitivo"),CEILING(Q34 * K34, 0.5), IF(I34="asteriscato", "inserire a mano", "")))) ) -> 2
A35: =VLOOKUP(B35,FVM_update!A:B,2,0) -> 5998 | B35: ZERBIN | C35: AS Intomatici | D35: =VLOOKUP(B35,FVM_update!A:F,6,0) -> Cremonese | E35: =VLOOKUP(B35,FVM_update!A:E,4,0) -> E;W | F35: Standard | G35: 45839 | H35: =IF(F35="Vivaio", DATE(2999, 12, 31), IF(F35="Standard", DATE(YEAR(G35)+1, MONTH(G35), DAY(G35)), IF(F35="Standard Inverno", DATE(2026, 7, 1), IF(OR(F35="Diritto 1+1", F35="Obbligo 1+1"), DATE(YEAR(G35)+2, MONTH(G35), DAY(G35)), IF(F35="Obbligo 1+2", DATE(YEAR(G35)+3, MONTH(G35), DAY(G35)), IF(OR(F35="Inverno Obbligo 1,5", F35="Inverno Diritto 0,5 + 1"), DATE(YEAR(G35)+1, MONTH(G35)+6, DAY(G35)), IF(F35="Inverno Obbligo 2,5", DATE(YEAR(G35)+2, MONTH(G35)+6, DAY(G35)), G35) ) ) ) ) ) ) -> 46204 | I35: Svincolo pausa invernale | J35: =VLOOKUP(A35,Asteriscati25!B:N,13,0) -> #N/A | L35: =VLOOKUP(B35,Rose!B:D,3,0) -> #REF! | M35: =VLOOKUP(B35,FVM_Asta2526!A:N,14,0) -> 31 | N35: =VLOOKUP(A35,FVM_update!B:N,13,0) -> 13 | O35: =VLOOKUP(B35,'FVM_1luglio-31luglio25'!D:Q,14,0) -> 12 | P35: =IFERROR(N35,O35) -> 13 | Q35: =IF(OR(F35="Standard",F35="Standard Inverno"),CEILING((M35/10),0.5), IF(OR(F35="Diritto 1+1",M35="Inverno Diritto 0,5 + 1"),CEILING((M35/10)*1.3,0.5), CEILING((M35/10)*1.15,0.5))) -> 3.5 | R35: =IF(I35="vivaio", 0.5, IF(OR(I35="asta", I35="Svincolato riconferma anno corrente", I35="vivaio", I35="promosso da vivaio"), Q35, IF(OR(I35="asta riparazione", I35="Svincolato obbligo anno precedente", I35="Svincolo pausa invernale"), MAX(0.5, CEILING(Q35 / 2, 0.5)), IF(OR(I35="ceduto in prestito", I35="acquisito in prestito", I35="acquistato tit definitivo", I35="Ceduto tit definitivo"),CEILING(Q35 * K35, 0.5), IF(I35="asteriscato", "inserire a mano", "")))) ) -> 2
A36: =VLOOKUP(B36,FVM_update!A:B,2,0) -> 6151 | B36: PERRONE | C36: AS Intomatici | D36: =VLOOKUP(B36,FVM_update!A:F,6,0) -> Como | E36: =VLOOKUP(B36,FVM_update!A:E,4,0) -> M;C | F36: Standard | G36: 45839 | H36: =IF(F36="Vivaio", DATE(2999, 12, 31), IF(F36="Standard", DATE(YEAR(G36)+1, MONTH(G36), DAY(G36)), IF(F36="Standard Inverno", DATE(2026, 7, 1), IF(OR(F36="Diritto 1+1", F36="Obbligo 1+1"), DATE(YEAR(G36)+2, MONTH(G36), DAY(G36)), IF(F36="Obbligo 1+2", DATE(YEAR(G36)+3, MONTH(G36), DAY(G36)), IF(OR(F36="Inverno Obbligo 1,5", F36="Inverno Diritto 0,5 + 1"), DATE(YEAR(G36)+1, MONTH(G36)+6, DAY(G36)), IF(F36="Inverno Obbligo 2,5", DATE(YEAR(G36)+2, MONTH(G36)+6, DAY(G36)), G36) ) ) ) ) ) ) -> 46204 | I36: Acquisito in prestito | J36: =VLOOKUP(A36,Asteriscati25!B:N,13,0) -> #N/A | K36: 1 | L36: =VLOOKUP(B36,Rose!B:D,3,0) -> #REF! | M36: =VLOOKUP(B36,FVM_Asta2526!A:N,14,0) -> 21 | N36: =VLOOKUP(A36,FVM_update!B:N,13,0) -> 45 | O36: =VLOOKUP(B36,'FVM_1luglio-31luglio25'!D:Q,14,0) -> 13 | P36: =IFERROR(N36,O36) -> 45 | Q36: =IF(OR(F36="Standard",F36="Standard Inverno"),CEILING((M36/10),0.5), IF(OR(F36="Diritto 1+1",M36="Inverno Diritto 0,5 + 1"),CEILING((M36/10)*1.3,0.5), CEILING((M36/10)*1.15,0.5))) -> 2.5 | R36: =IF(I36="vivaio", 0.5, IF(OR(I36="asta", I36="Svincolato riconferma anno corrente", I36="vivaio", I36="promosso da vivaio"), Q36, IF(OR(I36="asta riparazione", I36="Svincolato obbligo anno precedente", I36="Svincolo pausa invernale"), MAX(0.5, CEILING(Q36 / 2, 0.5)), IF(OR(I36="ceduto in prestito", I36="acquisito in prestito", I36="acquistato tit definitivo", I36="Ceduto tit definitivo"),CEILING(Q36 * K36, 0.5), IF(I36="asteriscato", "inserire a mano", "")))) ) -> 2.5 | T36: Werder
